<?xml version="1.0" encoding="utf-8"?>
<!-- =================================================================================== -->
<!-- |    This document was autogenerated by xacro from crustcrawler.xacro             | -->
<!-- |    EDITING THIS FILE BY HAND IS NOT RECOMMENDED                                 | -->
<!-- =================================================================================== -->
<robot name="CrustCrawler" xmlns:xacro="http://www.ros.org/wiki/xacro">
  <link name="base_link">
    <visual>
      <geometry>
        <cylinder length="0" radius="0.1"/>
      </geometry>
      <origin rpy="0 0 0" xyz="0 0 0"/>
    </visual>
  </link>
  <link name="link1">
    <visual>
      <geometry>
        <box size="0.01 0.01 0.22"/>
      </geometry>
      <origin rpy="0 0 0" xyz="0 0 -0.0275"/>
    </visual>
    <collision>
      <geometry>
        <box size="0.22 0.01 0.01"/>
      </geometry>
      <origin rpy="0 0 0" xyz="0 0 -0.0275"/>
    </collision>
    <inertial>
      <mass value="0.22501148645"/>
      <origin rpy="0 0 0" xyz="0 0 0.00375"/>
      <inertia ixx="1.0" ixy="0.0" ixz="0.0" iyy="1.0" iyz="0.0" izz="1.0"/>
    </inertial>
  </link>
  <link name="link2">
    <visual>
      <geometry>
        <box size="0.22 0.01 0.01"/>
      </geometry>
      <origin rpy="0 0 0" xyz="0.11 0 0"/>
    </visual>
    <collision>
      <geometry>
        <box size="0.22 0.01 0.01"/>
      </geometry>
      <origin rpy="0 0 0" xyz="0.11 0 0"/>
    </collision>
    <inertial>
      <mass value="0.21285774246"/>
      <inertia ixx="1.0" ixy="0.0" ixz="0.0" iyy="1.0" iyz="0.0" izz="1.0"/>
    </inertial>
  </link>
  <link name="link3">
    <visual>
      <geometry>
        <box size="0.15 0.01 0.01"/>
      </geometry>
      <origin rpy="0 0 0" xyz="0.075 0 0"/>
    </visual>
    <collision>
      <geometry>
        <box size="0.15 0.01 0.01"/>
      </geometry>
      <origin rpy="0 0 0" xyz="0.075 0 0"/>
    </collision>
    <inertial>
      <mass value="0.28725035108"/>
      <inertia ixx="1.0" ixy="0.0" ixz="0.0" iyy="1.0" iyz="0.0" izz="1.0"/>
    </inertial>
  </link>
  <link name="link4">
    <visual>
      <geometry>
        <box size="0.01 0.01 0.01"/>
      </geometry>
      <origin rpy="0 0 0" xyz="0 0 0"/>
    </visual>
    <inertial>
      <mass value="0.0"/>
      <inertia ixx="0.0" ixy="0.0" ixz="0.0" iyy="0.0" iyz="0.0" izz="0.0"/>
    </inertial>
  </link>
  <joint name="FirstJoint" type="revolute">
    <axis xyz="0 0 1"/>
    <limit effort="1000.0" lower="0.0" upper="6.283" velocity="0.5"/>
    <parent link="base_link"/>
    <child link="link1"/>
    <origin xyz="0 0 0.055"/>
  </joint>
  <joint name="SecondJoint" type="revolute">
    <axis xyz="0 0 1"/>
    <limit effort="1000.0" lower="-0.3" upper="3.1415" velocity="0.5"/>
    <parent link="link1"/>
    <child link="link2"/>
    <origin rpy="1.57075 0 0" xyz="0 0 0"/>
  </joint>
  <joint name="ThirdJoint" type="revolute">
    <axis xyz="0 0 1"/>
    <limit effort="1000.0" lower="2.8" upper="-3" velocity="0.5"/>
    <parent link="link2"/>
    <child link="link3"/>
    <origin rpy="0 0 0" xyz="0.22 0 0"/>
  </joint>
  <joint name="PayloadJoint" type="fixed">
    <parent link="link3"/>
    <child link="link4"/>
    <origin rpy="0 0 0" xyz="0.15 0 0"/>
  </joint>
</robot>

