<?xml version="1.0" encoding="utf-8"?>
<!-- =================================================================================== -->
<!-- |    This document was autogenerated by xacro from crustcrawler.xacro             | -->
<!-- |    EDITING THIS FILE BY HAND IS NOT RECOMMENDED                                 | -->
<!-- =================================================================================== -->
<robot name="CrustCrawler" xmlns:xacro="http://www.ros.org/wiki/xacro">
  <link name="world"/>
  <joint name="fixed" type="fixed">
    <parent link="world"/>
    <child link="base"/>
  </joint>
  <link name="base">
    <collision>
      <origin rpy="0 0 0" xyz="0 0 0.005"/>
      <geometry>
        <box size="0.01 0.01 0.01"/>
      </geometry>
    </collision>
    <visual>
      <origin rpy="0 0 0" xyz="0 0 0.005"/>
      <geometry>
        <box size="0.01 0.01 0.01"/>
      </geometry>
    </visual>
    <inertial>
      <origin rpy="0 0 0" xyz="0 0 0.005"/>
      <mass value="0.22501148645"/>
      <inertia ixx="0.0" ixy="0.0" ixz="0.0" iyy="0.0" iyz="0.0" izz="0.0"/>
    </inertial>
  </link>
  <joint name="joint_1" type="revolute">
    <axis xyz="0 0 1"/>
    <limit effort="1000.0" lower="0.0" upper="6.283" velocity="0.5"/>
    <parent link="base"/>
    <child link="link1"/>
    <origin rpy="0 0 0" xyz="0 0 0.01"/>
  </joint>
  <!-- link 1 -->
  <link name="link1">
    <collision>
      <origin rpy="0 0 0" xyz="0 0 0.5"/>
      <geometry>
        <box size="0.01 0.01 1.055"/>
      </geometry>
    </collision>
    <visual>
      <origin rpy="0 0 0" xyz="0 0 0.5275"/>
      <geometry>
        <box size="0.01 0.01 1.055"/>
      </geometry>
    </visual>
    <inertial>
      <origin rpy="0 0 0" xyz="0.5275 0 0"/>
      <mass value="0.22501148645"/>
      <inertia ixx="1.0" ixy="0.0" ixz="0.0" iyy="1.0" iyz="0.0" izz="1.0"/>
    </inertial>
  </link>
  <joint name="joint_2" type="revolute">
    <origin rpy="1.57075 0 0" xyz="0 0 1.055"/>
    <axis xyz="0 0 1"/>
    <limit effort="1000.0" lower="0.0" upper="6.283" velocity="0.5"/>
    <parent link="link1"/>
    <child link="link2"/>
  </joint>
  <!-- link 2 -->
  <link name="link2">
    <collision>
      <origin rpy="0 0 0" xyz="0.11 0 0"/>
      <geometry>
        <box size="0.22 0.01 0.01"/>
      </geometry>
    </collision>
    <visual>
      <origin rpy="0 0 0" xyz="0.11 0 0"/>
      <geometry>
        <box size="0.22 0.01 0.01"/>
      </geometry>
    </visual>
    <inertial>
      <origin rpy="0 0 0" xyz="0 0 0.11"/>
      <mass value="0.21285774246"/>
      <inertia ixx="1.0" ixy="0.0" ixz="0.0" iyy="1.0" iyz="0.0" izz="1.0"/>
    </inertial>
  </link>
  <joint name="joint_3" type="revolute">
    <axis xyz="0 0 1"/>
    <limit effort="1000.0" lower="0.0" upper="6.283" velocity="0.5"/>
    <parent link="link2"/>
    <child link="link3"/>
    <origin rpy="0 0 0" xyz="0.22 0 0"/>
  </joint>
  <!-- link 3 -->
  <link name="link3">
    <collision>
      <origin rpy="0 0 0" xyz="0.075 0 0"/>
      <geometry>
        <box size=" 0.15 0.01 0.01"/>
      </geometry>
    </collision>
    <visual>
      <origin rpy="0 0 0" xyz="0.075 0 0"/>
      <geometry>
        <box size="0.15 0.01 0.01 "/>
      </geometry>
    </visual>
    <inertial>
      <origin rpy="0 0 0" xyz="0.075 0 0 "/>
      <mass value="0.28725035108"/>
      <inertia ixx="1.0" ixy="0.0" ixz="0.0" iyy="1.0" iyz="0.0" izz="1.0"/>
    </inertial>
  </link>
  <!--
  <link name="link1">
    <visual>
      <geometry>
        <box size="${LinkWidth} ${LinkWidth} ${L1}"/>
      </geometry>
      <origin rpy="0 0 0" xyz="0 0 ${-L1+L1/2}"/>
    </visual>

    <collision>
      <geometry>
        <box size="${L2} ${LinkWidth} ${LinkWidth}"/>
      </geometry>
      <origin rpy="0 0 0" xyz="0 0 ${-L1+L1/2}"/>
    </collision>

    <inertial>
      <mass value="${m1}"/>
      <origin rpy="0 0 0" xyz="0 0 ${-L1+Lc}"/>
      <inertia ixx="1.0" ixy="0.0" ixz="0.0"
               iyy="1.0" iyz="0.0"
               izz="1.0"/>
    </inertial>
  </link>


  <link name="link2">
    <visual>
      <geometry>
        <box size="${L2} ${LinkWidth} ${LinkWidth}"/>
      </geometry>
      <origin rpy="0 0 0" xyz="${L2/2} 0 0"/>
    </visual>

    <collision>
      <geometry>
        <box size="${L2} ${LinkWidth} ${LinkWidth}"/>
      </geometry>
      <origin rpy="0 0 0" xyz="${L2/2} 0 0"/>
    </collision>

    <inertial>
      <mass value="${m2}"/>
      <origin rpy="0 0 0" xyz="0 0 ${Lc2}"/>
      <inertia ixx="1.0" ixy="0.0" ixz="0.0"
               iyy="1.0" iyz="0.0"
               izz="1.0"/>
    </inertial>
  </link>

  <link name="link3">
    <visual>
      <geometry>
        <box size="${Lcp} ${LinkWidth} ${LinkWidth}"/>
      </geometry>
      <origin rpy="0 0 0" xyz="${Lcp/2} 0 0"/>
    </visual>

    <collision>
      <geometry>
        <box size="${Lcp} ${LinkWidth} ${LinkWidth}"/>
      </geometry>
      <origin rpy="0 0 0" xyz="${Lcp/2} 0 0"/>
    </collision>

    <inertial>
      <mass value="${m3}"/>
      <origin rpy="0 0 0" xyz="0 0 ${Lc3}"/>
      <inertia ixx="1.0" ixy="0.0" ixz="0.0"
               iyy="1.0" iyz="0.0"
               izz="1.0"/>
    </inertial>
  </link>

  <link name="link4">
    <visual>
      <geometry>
        <box size="${LinkWidth} ${LinkWidth} ${LinkWidth}"/>
      </geometry>
      <origin rpy="0 0 0" xyz="0 0 0"/>
    </visual>

    <collision>
      <geometry>
        <box size="${Lcp} ${LinkWidth} ${LinkWidth}"/>
      </geometry>
      <origin rpy="0 0 0" xyz="${Lcp/2} 0 0"/>
    </collision>

    <inertial>
      <mass value="${mp}"/>
      <origin rpy="0 0 0" xyz="0 0 0"/>
      <inertia ixx="1.0" ixy="0.0" ixz="0.0"
               iyy="1.0" iyz="0.0"
               izz="1.0"/>
    </inertial>
  </link>


  <joint name="fixed" type="fixed">
    <parent link="world"/>
    <child link="base_link"/>
  </joint>

  <joint name="FirstJoint" type="revolute">
    <axis xyz="0 0 1"/>
    <limit effort="1000.0" lower="0.0" upper="${M_pi*2}" velocity="0.5"/>
    <parent link="base_link"/>
    <child link="link1"/>
    <origin xyz="0 0 ${L1}" rpy = "0 0 0"/>
  </joint>

  <joint name="SecondJoint" type="revolute">
    <axis xyz="0 0 1"/>
    <limit effort="1000.0" lower="-0.3" upper="${M_pi}" velocity="0.5"/>
    <parent link="link1"/>
    <child link="link2"/>
    <origin xyz="0 0 0" rpy="${M_pi/2} 0 0"/>
  </joint>


  <joint name="ThirdJoint" type="revolute">
    <axis xyz="0 0 1"/>
    <limit effort="1000.0" lower="-3" upper="3" velocity="0.5"/>
    <parent link="link2"/>
    <child link="link3"/>
    <origin xyz="${L2} 0 0" rpy="0 0 0"/>
  </joint>

  <joint name="PayloadJoint" type="fixed">
    <parent link="link3"/>
    <child link="link4"/>
    <origin xyz="${Lcp} 0 0" rpy="0 0 0"/>
  </joint> -->
</robot>

