<?xml version="1.0" encoding="utf-8"?>
<!-- =================================================================================== -->
<!-- |    This document was autogenerated by xacro from first.xacro                    | -->
<!-- |    EDITING THIS FILE BY HAND IS NOT RECOMMENDED                                 | -->
<!-- =================================================================================== -->
<robot name="CrustCrawler" xmlns:xacro="http://www.ros.org/wiki/xacro">
  <link name="base_link">
    <visual>
      <geometry>
        <cylinder length="0" radius="0.1"/>
      </geometry>
      <origin rpy="0 0 0" xyz="0 0 0"/>
    </visual>
  </link>
  <link name="link1">
    <visual>
      <geometry>
        <box size="0.01 0.01 0.055"/>
      </geometry>
      <origin rpy="0 0 0" xyz="0 0 -0.0275"/>
    </visual>
  </link>
  <link name="link2">
    <visual>
      <geometry>
        <box size="0.22 0.01 0.01"/>
      </geometry>
      <origin rpy="0 0 0" xyz="0.11 0 0"/>
    </visual>
  </link>
  <link name="link3">
    <visual>
      <geometry>
        <box size="0.15 0.01 0.01"/>
      </geometry>
      <origin rpy="0 0 0" xyz="0.075 0 0"/>
    </visual>
  </link>
  <joint name="FirstJoint" type="revolute">
    <axis xyz="0 0 1"/>
    <limit effort="1000.0" lower="0.0" upper="6.283" velocity="0.5"/>
    <parent link="base_link"/>
    <child link="link1"/>
    <origin xyz="0 0 0.055"/>
  </joint>
  <joint name="SecondJoint" type="revolute">
    <axis xyz="0 0 1"/>
    <limit effort="1000.0" lower="-0.3" upper="3.1415" velocity="0.5"/>
    <parent link="link1"/>
    <child link="link2"/>
    <origin rpy="1.57075 0 0" xyz="0 0 0"/>
  </joint>
  <joint name="ThirdJoint" type="revolute">
    <axis xyz="0 0 1"/>
    <limit effort="1000.0" lower="2.8" upper="-3" velocity="0.5"/>
    <parent link="link2"/>
    <child link="link3"/>
    <origin rpy="0 0 0" xyz="0.22 0 0"/>
  </joint>
</robot>

